DEBUG 2019-03-25 17:58:48,212 django.db.backends.execute:111 - (0.143) SELECT "django_session"."session_key", "django_session"."session_data", "django_session"."expire_date" FROM "django_session" WHERE ("django_session"."expire_date" > '2019-03-25T17:58:48.049494+00:00'::timestamptz AND "django_session"."session_key" = '8gmznsc4vsiyqn6upkwla1437gs1q52d'); args=(datetime.datetime(2019, 3, 25, 17, 58, 48, 49494, tzinfo=<UTC>), '8gmznsc4vsiyqn6upkwla1437gs1q52d')
DEBUG 2019-03-25 18:05:58,997 django.template._resolve_lookup:878 - Exception while resolving variable 'is_popup' in template 'admin/login.html'.
Traceback (most recent call last):
  File "/webapps/elections2019/venv/lib/python3.5/site-packages/django/template/base.py", line 835, in _resolve_lookup
    current = current[bit]
  File "/webapps/elections2019/venv/lib/python3.5/site-packages/django/template/context.py", line 83, in __getitem__
    raise KeyError(key)
KeyError: 'is_popup'

During handling of the above exception, another exception occurred:

Traceback (most recent call last):
  File "/webapps/elections2019/venv/lib/python3.5/site-packages/django/template/base.py", line 841, in _resolve_lookup
    if isinstance(current, BaseContext) and getattr(type(current), bit):
AttributeError: type object 'RequestContext' has no attribute 'is_popup'

During handling of the above exception, another exception occurred:

Traceback (most recent call last):
  File "/webapps/elections2019/venv/lib/python3.5/site-packages/django/template/base.py", line 849, in _resolve_lookup
    current = current[int(bit)]
ValueError: invalid literal for int() with base 10: 'is_popup'

During handling of the above exception, another exception occurred:

Traceback (most recent call last):
  File "/webapps/elections2019/venv/lib/python3.5/site-packages/django/template/base.py", line 856, in _resolve_lookup
    (bit, current))  # missing attribute
django.template.base.VariableDoesNotExist: Failed lookup for key [is_popup] in [{'None': None, 'True': True, 'False': False}, {'MEDIA_URL': '/elections2019/static/images/', 'csrf_token': <SimpleLazyObject: <function csrf.<locals>._get_val at 0x7f7541234ea0>>, 'user': <SimpleLazyObject: <django.contrib.auth.models.AnonymousUser object at 0x7f754120a860>>, 'DEFAULT_MESSAGE_LEVELS': {'SUCCESS': 25, 'ERROR': 40, 'INFO': 20, 'WARNING': 30, 'DEBUG': 10}, 'request': <WSGIRequest: GET '/general_elections/admin/login/?next=/general_elections/admin/'>, 'perms': <django.contrib.auth.context_processors.PermWrapper object at 0x7f75411cdda0>, 'messages': <django.contrib.messages.storage.fallback.FallbackStorage object at 0x7f754120a828>}, {}, {'site_name': '202.141.80.161', 'site_header': 'Django administration', 'title': 'Log in', 'has_permission': False, 'LANGUAGE_CODE': 'en-us', 'next': '/general_elections/admin/', 'form': <AdminAuthenticationForm bound=False, valid=Unknown, fields=(username;password)>, 'available_apps': [], 'username': '', 'site_title': 'Django site admin', 'view': <django.contrib.auth.views.LoginView object at 0x7f754120a9b0>, 'app_path': '/general_elections/admin/login/?next=/general_elections/admin/', 'site_url': '/', 'LANGUAGE_BIDI': False, 'site': <django.contrib.sites.requests.RequestSite object at 0x7f754120ac18>}]
DEBUG 2019-03-25 18:05:58,999 django.template._resolve_lookup:878 - Exception while resolving variable 'is_popup' in template 'admin/login.html'.
Traceback (most recent call last):
  File "/webapps/elections2019/venv/lib/python3.5/site-packages/django/template/base.py", line 835, in _resolve_lookup
    current = current[bit]
  File "/webapps/elections2019/venv/lib/python3.5/site-packages/django/template/context.py", line 83, in __getitem__
    raise KeyError(key)
KeyError: 'is_popup'

During handling of the above exception, another exception occurred:

Traceback (most recent call last):
  File "/webapps/elections2019/venv/lib/python3.5/site-packages/django/template/base.py", line 841, in _resolve_lookup
    if isinstance(current, BaseContext) and getattr(type(current), bit):
AttributeError: type object 'RequestContext' has no attribute 'is_popup'

During handling of the above exception, another exception occurred:

Traceback (most recent call last):
  File "/webapps/elections2019/venv/lib/python3.5/site-packages/django/template/base.py", line 849, in _resolve_lookup
    current = current[int(bit)]
ValueError: invalid literal for int() with base 10: 'is_popup'

During handling of the above exception, another exception occurred:

Traceback (most recent call last):
  File "/webapps/elections2019/venv/lib/python3.5/site-packages/django/template/base.py", line 856, in _resolve_lookup
    (bit, current))  # missing attribute
django.template.base.VariableDoesNotExist: Failed lookup for key [is_popup] in [{'None': None, 'True': True, 'False': False}, {'MEDIA_URL': '/elections2019/static/images/', 'csrf_token': <SimpleLazyObject: <function csrf.<locals>._get_val at 0x7f7541234ea0>>, 'user': <SimpleLazyObject: <django.contrib.auth.models.AnonymousUser object at 0x7f754120a860>>, 'DEFAULT_MESSAGE_LEVELS': {'SUCCESS': 25, 'ERROR': 40, 'INFO': 20, 'WARNING': 30, 'DEBUG': 10}, 'request': <WSGIRequest: GET '/general_elections/admin/login/?next=/general_elections/admin/'>, 'perms': <django.contrib.auth.context_processors.PermWrapper object at 0x7f75411cdda0>, 'messages': <django.contrib.messages.storage.fallback.FallbackStorage object at 0x7f754120a828>}, {}, {'site_name': '202.141.80.161', 'site_header': 'Django administration', 'title': 'Log in', 'has_permission': False, 'LANGUAGE_CODE': 'en-us', 'next': '/general_elections/admin/', 'form': <AdminAuthenticationForm bound=False, valid=Unknown, fields=(username;password)>, 'available_apps': [], 'username': '', 'site_title': 'Django site admin', 'view': <django.contrib.auth.views.LoginView object at 0x7f754120a9b0>, 'app_path': '/general_elections/admin/login/?next=/general_elections/admin/', 'site_url': '/', 'LANGUAGE_BIDI': False, 'site': <django.contrib.sites.requests.RequestSite object at 0x7f754120ac18>}]
ERROR 2019-03-25 18:06:14,542 django.request.handle_uncaught_exception:118 - Internal Server Error: /general_elections/admin_login/
Traceback (most recent call last):
  File "/webapps/elections2019/venv/lib/python3.5/site-packages/django/core/handlers/exception.py", line 35, in inner
    response = get_response(request)
  File "/webapps/elections2019/venv/lib/python3.5/site-packages/django/core/handlers/base.py", line 128, in _get_response
    response = self.process_exception_by_middleware(e, request)
  File "/webapps/elections2019/venv/lib/python3.5/site-packages/django/core/handlers/base.py", line 126, in _get_response
    response = wrapped_callback(request, *callback_args, **callback_kwargs)
  File "/webapps/elections2019/IITG_General_Elections/general_elections/views/views_admin.py", line 142, in admin_login_new
    username = request.session.get('mail', None).split('@')[0]
AttributeError: 'NoneType' object has no attribute 'split'
ERROR 2019-03-25 18:06:17,216 django.request.handle_uncaught_exception:118 - Internal Server Error: /general_elections/admin_login/
Traceback (most recent call last):
  File "/webapps/elections2019/venv/lib/python3.5/site-packages/django/core/handlers/exception.py", line 35, in inner
    response = get_response(request)
  File "/webapps/elections2019/venv/lib/python3.5/site-packages/django/core/handlers/base.py", line 128, in _get_response
    response = self.process_exception_by_middleware(e, request)
  File "/webapps/elections2019/venv/lib/python3.5/site-packages/django/core/handlers/base.py", line 126, in _get_response
    response = wrapped_callback(request, *callback_args, **callback_kwargs)
  File "/webapps/elections2019/IITG_General_Elections/general_elections/views/views_admin.py", line 142, in admin_login_new
    username = request.session.get('mail', None).split('@')[0]
AttributeError: 'NoneType' object has no attribute 'split'
ERROR 2019-03-25 18:06:17,682 django.request.handle_uncaught_exception:118 - Internal Server Error: /general_elections/admin_login/
Traceback (most recent call last):
  File "/webapps/elections2019/venv/lib/python3.5/site-packages/django/core/handlers/exception.py", line 35, in inner
    response = get_response(request)
  File "/webapps/elections2019/venv/lib/python3.5/site-packages/django/core/handlers/base.py", line 128, in _get_response
    response = self.process_exception_by_middleware(e, request)
  File "/webapps/elections2019/venv/lib/python3.5/site-packages/django/core/handlers/base.py", line 126, in _get_response
    response = wrapped_callback(request, *callback_args, **callback_kwargs)
  File "/webapps/elections2019/IITG_General_Elections/general_elections/views/views_admin.py", line 142, in admin_login_new
    username = request.session.get('mail', None).split('@')[0]
AttributeError: 'NoneType' object has no attribute 'split'
ERROR 2019-03-25 18:06:19,672 django.request.handle_uncaught_exception:118 - Internal Server Error: /general_elections/admin_login/
Traceback (most recent call last):
  File "/webapps/elections2019/venv/lib/python3.5/site-packages/django/core/handlers/exception.py", line 35, in inner
    response = get_response(request)
  File "/webapps/elections2019/venv/lib/python3.5/site-packages/django/core/handlers/base.py", line 128, in _get_response
    response = self.process_exception_by_middleware(e, request)
  File "/webapps/elections2019/venv/lib/python3.5/site-packages/django/core/handlers/base.py", line 126, in _get_response
    response = wrapped_callback(request, *callback_args, **callback_kwargs)
  File "/webapps/elections2019/IITG_General_Elections/general_elections/views/views_admin.py", line 142, in admin_login_new
    username = request.session.get('mail', None).split('@')[0]
AttributeError: 'NoneType' object has no attribute 'split'
ERROR 2019-03-25 18:09:04,067 django.request.handle_uncaught_exception:118 - Internal Server Error: /general_elections/
Traceback (most recent call last):
  File "/webapps/elections2019/venv/lib/python3.5/site-packages/django/core/handlers/exception.py", line 35, in inner
    response = get_response(request)
  File "/webapps/elections2019/venv/lib/python3.5/site-packages/django/core/handlers/base.py", line 113, in _get_response
    resolver_match = resolver.resolve(request.path_info)
  File "/webapps/elections2019/venv/lib/python3.5/site-packages/django/urls/resolvers.py", line 494, in resolve
    for pattern in self.url_patterns:
  File "/webapps/elections2019/venv/lib/python3.5/site-packages/django/utils/functional.py", line 36, in __get__
    res = instance.__dict__[self.name] = self.func(instance)
  File "/webapps/elections2019/venv/lib/python3.5/site-packages/django/urls/resolvers.py", line 536, in url_patterns
    patterns = getattr(self.urlconf_module, "urlpatterns", self.urlconf_module)
  File "/webapps/elections2019/venv/lib/python3.5/site-packages/django/utils/functional.py", line 36, in __get__
    res = instance.__dict__[self.name] = self.func(instance)
  File "/webapps/elections2019/venv/lib/python3.5/site-packages/django/urls/resolvers.py", line 529, in urlconf_module
    return import_module(self.urlconf_name)
  File "/webapps/elections2019/venv/lib/python3.5/importlib/__init__.py", line 126, in import_module
    return _bootstrap._gcd_import(name[level:], package, level)
  File "<frozen importlib._bootstrap>", line 986, in _gcd_import
  File "<frozen importlib._bootstrap>", line 969, in _find_and_load
  File "<frozen importlib._bootstrap>", line 958, in _find_and_load_unlocked
  File "<frozen importlib._bootstrap>", line 673, in _load_unlocked
  File "<frozen importlib._bootstrap_external>", line 665, in exec_module
  File "<frozen importlib._bootstrap>", line 222, in _call_with_frames_removed
  File "/webapps/elections2019/IITG_General_Elections/voting/urls.py", line 22, in <module>
    url('general_elections/', include('general_elections.urls')),
  File "/webapps/elections2019/venv/lib/python3.5/site-packages/django/urls/conf.py", line 34, in include
    urlconf_module = import_module(urlconf_module)
  File "/webapps/elections2019/venv/lib/python3.5/importlib/__init__.py", line 126, in import_module
    return _bootstrap._gcd_import(name[level:], package, level)
  File "<frozen importlib._bootstrap>", line 986, in _gcd_import
  File "<frozen importlib._bootstrap>", line 969, in _find_and_load
  File "<frozen importlib._bootstrap>", line 958, in _find_and_load_unlocked
  File "<frozen importlib._bootstrap>", line 673, in _load_unlocked
  File "<frozen importlib._bootstrap_external>", line 665, in exec_module
  File "<frozen importlib._bootstrap>", line 222, in _call_with_frames_removed
  File "/webapps/elections2019/IITG_General_Elections/general_elections/urls.py", line 2, in <module>
    from . import views
  File "/webapps/elections2019/IITG_General_Elections/general_elections/views/__init__.py", line 1, in <module>
    from .views_admin import *
  File "/webapps/elections2019/IITG_General_Elections/general_elections/views/views_admin.py", line 21, in <module>
    from authentication.authhelper import get_signin_url
  File "/webapps/elections2019/IITG_General_Elections/authentication/authhelper.py", line 69
    r = requests.post(token_url, data=post_data)
    ^
SyntaxError: invalid syntax
ERROR 2019-03-25 18:09:55,709 django.request.handle_uncaught_exception:118 - Internal Server Error: /general_elections/
Traceback (most recent call last):
  File "/webapps/elections2019/venv/lib/python3.5/site-packages/django/core/handlers/exception.py", line 35, in inner
    response = get_response(request)
  File "/webapps/elections2019/venv/lib/python3.5/site-packages/django/core/handlers/base.py", line 113, in _get_response
    resolver_match = resolver.resolve(request.path_info)
  File "/webapps/elections2019/venv/lib/python3.5/site-packages/django/urls/resolvers.py", line 494, in resolve
    for pattern in self.url_patterns:
  File "/webapps/elections2019/venv/lib/python3.5/site-packages/django/utils/functional.py", line 36, in __get__
    res = instance.__dict__[self.name] = self.func(instance)
  File "/webapps/elections2019/venv/lib/python3.5/site-packages/django/urls/resolvers.py", line 536, in url_patterns
    patterns = getattr(self.urlconf_module, "urlpatterns", self.urlconf_module)
  File "/webapps/elections2019/venv/lib/python3.5/site-packages/django/utils/functional.py", line 36, in __get__
    res = instance.__dict__[self.name] = self.func(instance)
  File "/webapps/elections2019/venv/lib/python3.5/site-packages/django/urls/resolvers.py", line 529, in urlconf_module
    return import_module(self.urlconf_name)
  File "/webapps/elections2019/venv/lib/python3.5/importlib/__init__.py", line 126, in import_module
    return _bootstrap._gcd_import(name[level:], package, level)
  File "<frozen importlib._bootstrap>", line 986, in _gcd_import
  File "<frozen importlib._bootstrap>", line 969, in _find_and_load
  File "<frozen importlib._bootstrap>", line 958, in _find_and_load_unlocked
  File "<frozen importlib._bootstrap>", line 673, in _load_unlocked
  File "<frozen importlib._bootstrap_external>", line 665, in exec_module
  File "<frozen importlib._bootstrap>", line 222, in _call_with_frames_removed
  File "/webapps/elections2019/IITG_General_Elections/voting/urls.py", line 22, in <module>
    url('general_elections/', include('general_elections.urls')),
  File "/webapps/elections2019/venv/lib/python3.5/site-packages/django/urls/conf.py", line 34, in include
    urlconf_module = import_module(urlconf_module)
  File "/webapps/elections2019/venv/lib/python3.5/importlib/__init__.py", line 126, in import_module
    return _bootstrap._gcd_import(name[level:], package, level)
  File "<frozen importlib._bootstrap>", line 986, in _gcd_import
  File "<frozen importlib._bootstrap>", line 969, in _find_and_load
  File "<frozen importlib._bootstrap>", line 958, in _find_and_load_unlocked
  File "<frozen importlib._bootstrap>", line 673, in _load_unlocked
  File "<frozen importlib._bootstrap_external>", line 665, in exec_module
  File "<frozen importlib._bootstrap>", line 222, in _call_with_frames_removed
  File "/webapps/elections2019/IITG_General_Elections/general_elections/urls.py", line 2, in <module>
    from . import views
  File "/webapps/elections2019/IITG_General_Elections/general_elections/views/__init__.py", line 1, in <module>
    from .views_admin import *
  File "/webapps/elections2019/IITG_General_Elections/general_elections/views/views_admin.py", line 21, in <module>
    from authentication.authhelper import get_signin_url
  File "/webapps/elections2019/IITG_General_Elections/authentication/authhelper.py", line 66
    r = requests.post(token_url, data=post_data)
    ^
SyntaxError: invalid syntax
ERROR 2019-03-25 18:09:57,982 django.request.handle_uncaught_exception:118 - Internal Server Error: /general_elections/
Traceback (most recent call last):
  File "/webapps/elections2019/venv/lib/python3.5/site-packages/django/core/handlers/exception.py", line 35, in inner
    response = get_response(request)
  File "/webapps/elections2019/venv/lib/python3.5/site-packages/django/core/handlers/base.py", line 113, in _get_response
    resolver_match = resolver.resolve(request.path_info)
  File "/webapps/elections2019/venv/lib/python3.5/site-packages/django/urls/resolvers.py", line 494, in resolve
    for pattern in self.url_patterns:
  File "/webapps/elections2019/venv/lib/python3.5/site-packages/django/utils/functional.py", line 36, in __get__
    res = instance.__dict__[self.name] = self.func(instance)
  File "/webapps/elections2019/venv/lib/python3.5/site-packages/django/urls/resolvers.py", line 536, in url_patterns
    patterns = getattr(self.urlconf_module, "urlpatterns", self.urlconf_module)
  File "/webapps/elections2019/venv/lib/python3.5/site-packages/django/utils/functional.py", line 36, in __get__
    res = instance.__dict__[self.name] = self.func(instance)
  File "/webapps/elections2019/venv/lib/python3.5/site-packages/django/urls/resolvers.py", line 529, in urlconf_module
    return import_module(self.urlconf_name)
  File "/webapps/elections2019/venv/lib/python3.5/importlib/__init__.py", line 126, in import_module
    return _bootstrap._gcd_import(name[level:], package, level)
  File "<frozen importlib._bootstrap>", line 986, in _gcd_import
  File "<frozen importlib._bootstrap>", line 969, in _find_and_load
  File "<frozen importlib._bootstrap>", line 958, in _find_and_load_unlocked
  File "<frozen importlib._bootstrap>", line 673, in _load_unlocked
  File "<frozen importlib._bootstrap_external>", line 665, in exec_module
  File "<frozen importlib._bootstrap>", line 222, in _call_with_frames_removed
  File "/webapps/elections2019/IITG_General_Elections/voting/urls.py", line 22, in <module>
    url('general_elections/', include('general_elections.urls')),
  File "/webapps/elections2019/venv/lib/python3.5/site-packages/django/urls/conf.py", line 34, in include
    urlconf_module = import_module(urlconf_module)
  File "/webapps/elections2019/venv/lib/python3.5/importlib/__init__.py", line 126, in import_module
    return _bootstrap._gcd_import(name[level:], package, level)
  File "<frozen importlib._bootstrap>", line 986, in _gcd_import
  File "<frozen importlib._bootstrap>", line 969, in _find_and_load
  File "<frozen importlib._bootstrap>", line 958, in _find_and_load_unlocked
  File "<frozen importlib._bootstrap>", line 673, in _load_unlocked
  File "<frozen importlib._bootstrap_external>", line 665, in exec_module
  File "<frozen importlib._bootstrap>", line 222, in _call_with_frames_removed
  File "/webapps/elections2019/IITG_General_Elections/general_elections/urls.py", line 2, in <module>
    from . import views
  File "/webapps/elections2019/IITG_General_Elections/general_elections/views/__init__.py", line 1, in <module>
    from .views_admin import *
  File "/webapps/elections2019/IITG_General_Elections/general_elections/views/views_admin.py", line 21, in <module>
    from authentication.authhelper import get_signin_url
  File "/webapps/elections2019/IITG_General_Elections/authentication/authhelper.py", line 66
    r = requests.post(token_url, data=post_data)
    ^
SyntaxError: invalid syntax
ERROR 2019-03-25 18:09:58,783 django.request.handle_uncaught_exception:118 - Internal Server Error: /general_elections/
Traceback (most recent call last):
  File "/webapps/elections2019/venv/lib/python3.5/site-packages/django/core/handlers/exception.py", line 35, in inner
    response = get_response(request)
  File "/webapps/elections2019/venv/lib/python3.5/site-packages/django/core/handlers/base.py", line 113, in _get_response
    resolver_match = resolver.resolve(request.path_info)
  File "/webapps/elections2019/venv/lib/python3.5/site-packages/django/urls/resolvers.py", line 494, in resolve
    for pattern in self.url_patterns:
  File "/webapps/elections2019/venv/lib/python3.5/site-packages/django/utils/functional.py", line 36, in __get__
    res = instance.__dict__[self.name] = self.func(instance)
  File "/webapps/elections2019/venv/lib/python3.5/site-packages/django/urls/resolvers.py", line 536, in url_patterns
    patterns = getattr(self.urlconf_module, "urlpatterns", self.urlconf_module)
  File "/webapps/elections2019/venv/lib/python3.5/site-packages/django/utils/functional.py", line 36, in __get__
    res = instance.__dict__[self.name] = self.func(instance)
  File "/webapps/elections2019/venv/lib/python3.5/site-packages/django/urls/resolvers.py", line 529, in urlconf_module
    return import_module(self.urlconf_name)
  File "/webapps/elections2019/venv/lib/python3.5/importlib/__init__.py", line 126, in import_module
    return _bootstrap._gcd_import(name[level:], package, level)
  File "<frozen importlib._bootstrap>", line 986, in _gcd_import
  File "<frozen importlib._bootstrap>", line 969, in _find_and_load
  File "<frozen importlib._bootstrap>", line 958, in _find_and_load_unlocked
  File "<frozen importlib._bootstrap>", line 673, in _load_unlocked
  File "<frozen importlib._bootstrap_external>", line 665, in exec_module
  File "<frozen importlib._bootstrap>", line 222, in _call_with_frames_removed
  File "/webapps/elections2019/IITG_General_Elections/voting/urls.py", line 22, in <module>
    url('general_elections/', include('general_elections.urls')),
  File "/webapps/elections2019/venv/lib/python3.5/site-packages/django/urls/conf.py", line 34, in include
    urlconf_module = import_module(urlconf_module)
  File "/webapps/elections2019/venv/lib/python3.5/importlib/__init__.py", line 126, in import_module
    return _bootstrap._gcd_import(name[level:], package, level)
  File "<frozen importlib._bootstrap>", line 986, in _gcd_import
  File "<frozen importlib._bootstrap>", line 969, in _find_and_load
  File "<frozen importlib._bootstrap>", line 958, in _find_and_load_unlocked
  File "<frozen importlib._bootstrap>", line 673, in _load_unlocked
  File "<frozen importlib._bootstrap_external>", line 665, in exec_module
  File "<frozen importlib._bootstrap>", line 222, in _call_with_frames_removed
  File "/webapps/elections2019/IITG_General_Elections/general_elections/urls.py", line 2, in <module>
    from . import views
  File "/webapps/elections2019/IITG_General_Elections/general_elections/views/__init__.py", line 1, in <module>
    from .views_admin import *
  File "/webapps/elections2019/IITG_General_Elections/general_elections/views/views_admin.py", line 21, in <module>
    from authentication.authhelper import get_signin_url
  File "/webapps/elections2019/IITG_General_Elections/authentication/authhelper.py", line 66
    r = requests.post(token_url, data=post_data)
    ^
SyntaxError: invalid syntax
ERROR 2019-03-25 18:14:05,699 django.request.handle_uncaught_exception:118 - Internal Server Error: /general_elections/authentication/gettoken/
Traceback (most recent call last):
  File "/webapps/elections2019/venv/lib/python3.5/site-packages/urllib3/connectionpool.py", line 594, in urlopen
    self._prepare_proxy(conn)
  File "/webapps/elections2019/venv/lib/python3.5/site-packages/urllib3/connectionpool.py", line 805, in _prepare_proxy
    conn.connect()
  File "/webapps/elections2019/venv/lib/python3.5/site-packages/urllib3/connection.py", line 308, in connect
    self._tunnel()
  File "/usr/lib/python3.5/http/client.py", line 832, in _tunnel
    message.strip()))
OSError: Tunnel connection failed: 403 Forbidden

During handling of the above exception, another exception occurred:

Traceback (most recent call last):
  File "/webapps/elections2019/venv/lib/python3.5/site-packages/requests/adapters.py", line 449, in send
    timeout=timeout
  File "/webapps/elections2019/venv/lib/python3.5/site-packages/urllib3/connectionpool.py", line 638, in urlopen
    _stacktrace=sys.exc_info()[2])
  File "/webapps/elections2019/venv/lib/python3.5/site-packages/urllib3/util/retry.py", line 398, in increment
    raise MaxRetryError(_pool, url, error or ResponseError(cause))
urllib3.exceptions.MaxRetryError: HTTPSConnectionPool(host='google.com', port=443): Max retries exceeded with url: / (Caused by ProxyError('Cannot connect to proxy.', OSError('Tunnel connection failed: 403 Forbidden',)))

During handling of the above exception, another exception occurred:

Traceback (most recent call last):
  File "/webapps/elections2019/venv/lib/python3.5/site-packages/django/core/handlers/exception.py", line 35, in inner
    response = get_response(request)
  File "/webapps/elections2019/venv/lib/python3.5/site-packages/django/core/handlers/base.py", line 128, in _get_response
    response = self.process_exception_by_middleware(e, request)
  File "/webapps/elections2019/venv/lib/python3.5/site-packages/django/core/handlers/base.py", line 126, in _get_response
    response = wrapped_callback(request, *callback_args, **callback_kwargs)
  File "/webapps/elections2019/IITG_General_Elections/authentication/views.py", line 33, in gettoken
    token = get_token_from_code(auth_code, redirect_uri)
  File "/webapps/elections2019/IITG_General_Elections/authentication/authhelper.py", line 64, in get_token_from_code
    logger.info(requests.get('https://google.com', proxies=proxies))
  File "/webapps/elections2019/venv/lib/python3.5/site-packages/requests/api.py", line 75, in get
    return request('get', url, params=params, **kwargs)
  File "/webapps/elections2019/venv/lib/python3.5/site-packages/requests/api.py", line 60, in request
    return session.request(method=method, url=url, **kwargs)
  File "/webapps/elections2019/venv/lib/python3.5/site-packages/requests/sessions.py", line 533, in request
    resp = self.send(prep, **send_kwargs)
  File "/webapps/elections2019/venv/lib/python3.5/site-packages/requests/sessions.py", line 646, in send
    r = adapter.send(request, **kwargs)
  File "/webapps/elections2019/venv/lib/python3.5/site-packages/requests/adapters.py", line 510, in send
    raise ProxyError(e, request=request)
requests.exceptions.ProxyError: HTTPSConnectionPool(host='google.com', port=443): Max retries exceeded with url: / (Caused by ProxyError('Cannot connect to proxy.', OSError('Tunnel connection failed: 403 Forbidden',)))
ERROR 2019-03-25 18:14:34,582 django.request.handle_uncaught_exception:118 - Internal Server Error: /general_elections/authentication/gettoken/
Traceback (most recent call last):
  File "/webapps/elections2019/venv/lib/python3.5/site-packages/urllib3/connectionpool.py", line 594, in urlopen
    self._prepare_proxy(conn)
  File "/webapps/elections2019/venv/lib/python3.5/site-packages/urllib3/connectionpool.py", line 805, in _prepare_proxy
    conn.connect()
  File "/webapps/elections2019/venv/lib/python3.5/site-packages/urllib3/connection.py", line 308, in connect
    self._tunnel()
  File "/usr/lib/python3.5/http/client.py", line 832, in _tunnel
    message.strip()))
OSError: Tunnel connection failed: 403 Forbidden

During handling of the above exception, another exception occurred:

Traceback (most recent call last):
  File "/webapps/elections2019/venv/lib/python3.5/site-packages/requests/adapters.py", line 449, in send
    timeout=timeout
  File "/webapps/elections2019/venv/lib/python3.5/site-packages/urllib3/connectionpool.py", line 638, in urlopen
    _stacktrace=sys.exc_info()[2])
  File "/webapps/elections2019/venv/lib/python3.5/site-packages/urllib3/util/retry.py", line 398, in increment
    raise MaxRetryError(_pool, url, error or ResponseError(cause))
urllib3.exceptions.MaxRetryError: HTTPSConnectionPool(host='google.com', port=443): Max retries exceeded with url: / (Caused by ProxyError('Cannot connect to proxy.', OSError('Tunnel connection failed: 403 Forbidden',)))

During handling of the above exception, another exception occurred:

Traceback (most recent call last):
  File "/webapps/elections2019/venv/lib/python3.5/site-packages/django/core/handlers/exception.py", line 35, in inner
    response = get_response(request)
  File "/webapps/elections2019/venv/lib/python3.5/site-packages/django/core/handlers/base.py", line 128, in _get_response
    response = self.process_exception_by_middleware(e, request)
  File "/webapps/elections2019/venv/lib/python3.5/site-packages/django/core/handlers/base.py", line 126, in _get_response
    response = wrapped_callback(request, *callback_args, **callback_kwargs)
  File "/webapps/elections2019/IITG_General_Elections/authentication/views.py", line 33, in gettoken
    token = get_token_from_code(auth_code, redirect_uri)
  File "/webapps/elections2019/IITG_General_Elections/authentication/authhelper.py", line 64, in get_token_from_code
    logger.info(requests.get('https://google.com', proxies=proxies))
  File "/webapps/elections2019/venv/lib/python3.5/site-packages/requests/api.py", line 75, in get
    return request('get', url, params=params, **kwargs)
  File "/webapps/elections2019/venv/lib/python3.5/site-packages/requests/api.py", line 60, in request
    return session.request(method=method, url=url, **kwargs)
  File "/webapps/elections2019/venv/lib/python3.5/site-packages/requests/sessions.py", line 533, in request
    resp = self.send(prep, **send_kwargs)
  File "/webapps/elections2019/venv/lib/python3.5/site-packages/requests/sessions.py", line 646, in send
    r = adapter.send(request, **kwargs)
  File "/webapps/elections2019/venv/lib/python3.5/site-packages/requests/adapters.py", line 510, in send
    raise ProxyError(e, request=request)
requests.exceptions.ProxyError: HTTPSConnectionPool(host='google.com', port=443): Max retries exceeded with url: / (Caused by ProxyError('Cannot connect to proxy.', OSError('Tunnel connection failed: 403 Forbidden',)))
